<?xml version="1.0" ?>
<!-- =================================================================================== -->
<!-- |    This document was autogenerated by xacro from simple_robot.urdf.xacro        | -->
<!-- |    EDITING THIS FILE BY HAND IS NOT RECOMMENDED                                 | -->
<!-- =================================================================================== -->
<robot name="simple_robot">
  <static>false</static>
  <!-- ros_control plugin -->
  <gazebo>
    <plugin filename="libgazebo_ros_control.so" name="gazebo_ros_control">
		</plugin>
  </gazebo>
  <link name="base_link">
          </link>
  <link name="chassis">
    <inertial>
      <mass value="1"/>
      <inertia ixx="0.004" ixy="0.0" ixz="0.0" iyy="0.004" iyz="0.0" izz="0.002"/>
    </inertial>
    <!--<pose>0 0 .1 0 0 0</pose>-->
    <collision name="collision">
      <geometry>
        <box size=".4 .2 .1"/>
      </geometry>
    </collision>
    <visual name="visual">
      <geometry>
        <box size=".4 .2 .1"/>
      </geometry>
    </visual>
  </link>
  <link name="castor">
    <inertial>
      <mass value=".1"/>
      <inertia ixx="0.004" ixy="0.0" ixz="0.0" iyy="0.004" iyz="0.0" izz="0.002"/>
    </inertial>
    <!--<pose>0 0 .4 0 0 0</pose>-->
    <collision name="collision">
      <geometry>
        <sphere radius=".05"/>
      </geometry>
      <surface>
        <friction>
          <ode>
            <mu>0</mu>
            <mu2>0</mu2>
          </ode>
        </friction>
      </surface>
    </collision>
    <visual name="visual">
      <geometry>
        <sphere radius=".05"/>
      </geometry>
    </visual>
  </link>
  <link name="left_wheel">
    <inertial>
      <mass value=".1"/>
      <inertia ixx="0.004" ixy="0.0" ixz="0.0" iyy="0.004" iyz="0.0" izz="0.002"/>
    </inertial>
    <pose>0.1 0.13 0.1 0 1.5707 1.5707</pose>
    <collision name="collision">
      <geometry>
        <cylinder length=".05" radius=".1"/>
      </geometry>
    </collision>
    <visual name="visual">
      <geometry>
        <cylinder length=".05" radius=".1"/>
      </geometry>
    </visual>
  </link>
  <link name="right_wheel">
    <inertial>
      <mass value=".1"/>
      <inertia ixx="0.004" ixy="0.0" ixz="0.0" iyy="0.004" iyz="0.0" izz="0.002"/>
    </inertial>
    <pose>0.1 0.13 0.1 0 1.5707 1.5707</pose>
    <collision name="collision">
      <geometry>
        <cylinder length=".05" radius=".1"/>
      </geometry>
    </collision>
    <visual name="visual">
      <geometry>
        <cylinder length=".05" radius=".1"/>
      </geometry>
    </visual>
  </link>
  <joint name="joint0" type="fixed">
    <parent link="base_link"/>
    <child link="chassis"/>
    <origin rpy="0 0 0" xyz="0 0 0"/>
    <axis xyz="0 1 0"/>
    <dynamics damping="0.7"/>
  </joint>
  <joint name="joint1" type="fixed">
    <parent link="chassis"/>
    <child link="castor"/>
    <origin rpy="0 0 0" xyz=".15 0 -.05"/>
    <axis xyz="0 1 0"/>
    <dynamics damping="0.7"/>
  </joint>
  <joint name="wheel_left_joint" type="continuous">
    <parent link="chassis"/>
    <child link="left_wheel"/>
    <origin rpy="0 1.5707 1.5707" xyz="-0.1 0.13 0"/>
    <axis xyz="0 0 1"/>
    <calibration rising="0.0"/>
    <dynamics damping="0.0" friction="0.0"/>
    <limit effort="30" velocity="2.0"/>
    <safety_controller k_position="15" k_velocity="10" soft_lower_limit="-2.0" soft_upper_limit="0.5"/>
  </joint>
  <joint name="wheel_right_joint" type="continuous">
    <parent link="chassis"/>
    <child link="right_wheel"/>
    <origin rpy="0 1.5707 1.5707" xyz="-0.1 -0.13 0"/>
    <axis xyz="0 0 1"/>
    <calibration rising="0.0"/>
    <dynamics damping="0.0" friction="0.0"/>
    <limit effort="30" velocity="2.0"/>
    <safety_controller k_position="15" k_velocity="10" soft_lower_limit="-2.0" soft_upper_limit="0.5"/>
  </joint>
  <transmission name="left_wheel_transmission">
    <type>transmission_interface/SimpleTransmission</type>
    <joint name="wheel_left_joint">
      <hardwareInterface>hardware_interface/VelocityJointInterface</hardwareInterface>
    </joint>
    <actuator name="left_wheel_actuator">
      <mechanicalReduction>7</mechanicalReduction>
      <hardwareInterface>VelocityJointInterface</hardwareInterface>
    </actuator>
  </transmission>
  <transmission name="right_wheel_transmission">
    <type>transmission_interface/SimpleTransmission</type>
    <joint name="wheel_right_joint">
      <hardwareInterface>hardware_interface/VelocityJointInterface</hardwareInterface>
    </joint>
    <actuator name="right_wheel_actuator">
      <mechanicalReduction>7</mechanicalReduction>
      <hardwareInterface>VelocityJointInterface</hardwareInterface>
    </actuator>
  </transmission>
</robot>

